Workbook

Sheet لوحة النتائج
A1: لوحة نتائج الاختبار التشخيصي
A3: الإعدادات
A4: حد الإتقان (نسبة مئوية) | B4: 0.6 | C4: خلية صفراء = قابلة للتعديل
A5: الدرجة الكلية للاختبار | B5: =المهارات!$G$27 -> 0
A6: درجة الإتقان | B6: =$B$4*$B$5 -> 0
A8: مؤشرات عامة
A9: عدد الطلاب | B9: عدد المرصودين | C9: متوسط الدرجة | D9: النسبة المئوية | E9: أعلى درجة | F9: أدنى درجة | G9: عدد المتقنين | H9: نسبة الإتقان | I9: الانحراف المعياري
A10: =COUNTA(التحليل!$A$3:$A$222) -> 220 | B10: =COUNT(التحليل!$C$3:$C$222) -> 0 | C10: =IFERROR(AVERAGE(التحليل!$C$3:$C$222),"") | D10: =IFERROR($C$10/$B$5,"") | E10: =IFERROR(MAX(التحليل!$C$3:$C$222),"") -> 0 | F10: =IFERROR(MIN(التحليل!$C$3:$C$222),"") -> 0 | G10: =COUNTIF(التحليل!$C$3:$C$222,">="&$B$6) -> 0 | H10: =IFERROR($G$10/$B$10,"") | I10: =IFERROR(STDEV(التحليل!$C$3:$C$222),"")
A11: النتائج حسب الفصل
A12: الفصل | B12: عدد الطلاب | C12: عدد المرصودين | D12: متوسط الدرجة | E12: النسبة المئوية | F12: أعلى درجة | G12: أدنى درجة | H12: عدد المتقنين | I12: نسبة الإتقان
A13: 10/1 | B13: =COUNTIF(التحليل!$B$3:$B$222,$A13) -> 21 | C13: =COUNTIFS(التحليل!$B$3:$B$222,$A13,التحليل!$C$3:$C$222,">=0") -> 0 | D13: =IFERROR(AVERAGEIF(التحليل!$B$3:$B$222,$A13,التحليل!$C$3:$C$222),"") | E13: =IFERROR($D13/$B$5,"") | F13: =IF($C13=0,"",_xlfn.MAXIFS(التحليل!$C$3:$C$222,التحليل!$B$3:$B$222,$A13)) | G13: =IF($C13=0,"",_xlfn.MINIFS(التحليل!$C$3:$C$222,التحليل!$B$3:$B$222,$A13)) | H13: =COUNTIFS(التحليل!$B$3:$B$222,$A13,التحليل!$C$3:$C$222,">="&$B$6) -> 0 | I13: =IFERROR($H13/$C13,"")
A14: 10/2 | B14: =COUNTIF(التحليل!$B$3:$B$222,$A14) -> 20 | C14: =COUNTIFS(التحليل!$B$3:$B$222,$A14,التحليل!$C$3:$C$222,">=0") -> 0 | D14: =IFERROR(AVERAGEIF(التحليل!$B$3:$B$222,$A14,التحليل!$C$3:$C$222),"") | E14: =IFERROR($D14/$B$5,"") | F14: =IF($C14=0,"",_xlfn.MAXIFS(التحليل!$C$3:$C$222,التحليل!$B$3:$B$222,$A14)) | G14: =IF($C14=0,"",_xlfn.MINIFS(التحليل!$C$3:$C$222,التحليل!$B$3:$B$222,$A14)) | H14: =COUNTIFS(التحليل!$B$3:$B$222,$A14,التحليل!$C$3:$C$222,">="&$B$6) -> 0 | I14: =IFERROR($H14/$C14,"")
A15: 10/3 | B15: =COUNTIF(التحليل!$B$3:$B$222,$A15) -> 22 | C15: =COUNTIFS(التحليل!$B$3:$B$222,$A15,التحليل!$C$3:$C$222,">=0") -> 0 | D15: =IFERROR(AVERAGEIF(التحليل!$B$3:$B$222,$A15,التحليل!$C$3:$C$222),"") | E15: =IFERROR($D15/$B$5,"") | F15: =IF($C15=0,"",_xlfn.MAXIFS(التحليل!$C$3:$C$222,التحليل!$B$3:$B$222,$A15)) | G15: =IF($C15=0,"",_xlfn.MINIFS(التحليل!$C$3:$C$222,التحليل!$B$3:$B$222,$A15)) | H15: =COUNTIFS(التحليل!$B$3:$B$222,$A15,التحليل!$C$3:$C$222,">="&$B$6) -> 0 | I15: =IFERROR($H15/$C15,"")
A16: 10/4 | B16: =COUNTIF(التحليل!$B$3:$B$222,$A16) -> 21 | C16: =COUNTIFS(التحليل!$B$3:$B$222,$A16,التحليل!$C$3:$C$222,">=0") -> 0 | D16: =IFERROR(AVERAGEIF(التحليل!$B$3:$B$222,$A16,التحليل!$C$3:$C$222),"") | E16: =IFERROR($D16/$B$5,"") | F16: =IF($C16=0,"",_xlfn.MAXIFS(التحليل!$C$3:$C$222,التحليل!$B$3:$B$222,$A16)) | G16: =IF($C16=0,"",_xlfn.MINIFS(التحليل!$C$3:$C$222,التحليل!$B$3:$B$222,$A16)) | H16: =COUNTIFS(التحليل!$B$3:$B$222,$A16,التحليل!$C$3:$C$222,">="&$B$6) -> 0 | I16: =IFERROR($H16/$C16,"")
A17: 10/5 | B17: =COUNTIF(التحليل!$B$3:$B$222,$A17) -> 21 | C17: =COUNTIFS(التحليل!$B$3:$B$222,$A17,التحليل!$C$3:$C$222,">=0") -> 0 | D17: =IFERROR(AVERAGEIF(التحليل!$B$3:$B$222,$A17,التحليل!$C$3:$C$222),"") | E17: =IFERROR($D17/$B$5,"") | F17: =IF($C17=0,"",_xlfn.MAXIFS(التحليل!$C$3:$C$222,التحليل!$B$3:$B$222,$A17)) | G17: =IF($C17=0,"",_xlfn.MINIFS(التحليل!$C$3:$C$222,التحليل!$B$3:$B$222,$A17)) | H17: =COUNTIFS(التحليل!$B$3:$B$222,$A17,التحليل!$C$3:$C$222,">="&$B$6) -> 0 | I17: =IFERROR($H17/$C17,"")
A18: 10/6 | B18: =COUNTIF(التحليل!$B$3:$B$222,$A18) -> 22 | C18: =COUNTIFS(التحليل!$B$3:$B$222,$A18,التحليل!$C$3:$C$222,">=0") -> 0 | D18: =IFERROR(AVERAGEIF(التحليل!$B$3:$B$222,$A18,التحليل!$C$3:$C$222),"") | E18: =IFERROR($D18/$B$5,"") | F18: =IF($C18=0,"",_xlfn.MAXIFS(التحليل!$C$3:$C$222,التحليل!$B$3:$B$222,$A18)) | G18: =IF($C18=0,"",_xlfn.MINIFS(التحليل!$C$3:$C$222,التحليل!$B$3:$B$222,$A18)) | H18: =COUNTIFS(التحليل!$B$3:$B$222,$A18,التحليل!$C$3:$C$222,">="&$B$6) -> 0 | I18: =IFERROR($H18/$C18,"")
A19: 10/7 | B19: =COUNTIF(التحليل!$B$3:$B$222,$A19) -> 23 | C19: =COUNTIFS(التحليل!$B$3:$B$222,$A19,التحليل!$C$3:$C$222,">=0") -> 0 | D19: =IFERROR(AVERAGEIF(التحليل!$B$3:$B$222,$A19,التحليل!$C$3:$C$222),"") | E19: =IFERROR($D19/$B$5,"") | F19: =IF($C19=0,"",_xlfn.MAXIFS(التحليل!$C$3:$C$222,التحليل!$B$3:$B$222,$A19)) | G19: =IF($C19=0,"",_xlfn.MINIFS(التحليل!$C$3:$C$222,التحليل!$B$3:$B$222,$A19)) | H19: =COUNTIFS(التحليل!$B$3:$B$222,$A19,التحليل!$C$3:$C$222,">="&$B$6) -> 0 | I19: =IFERROR($H19/$C19,"")
A20: 10/8 | B20: =COUNTIF(التحليل!$B$3:$B$222,$A20) -> 21 | C20: =COUNTIFS(التحليل!$B$3:$B$222,$A20,التحليل!$C$3:$C$222,">=0") -> 0 | D20: =IFERROR(AVERAGEIF(التحليل!$B$3:$B$222,$A20,التحليل!$C$3:$C$222),"") | E20: =IFERROR($D20/$B$5,"") | F20: =IF($C20=0,"",_xlfn.MAXIFS(التحليل!$C$3:$C$222,التحليل!$B$3:$B$222,$A20)) | G20: =IF($C20=0,"",_xlfn.MINIFS(التحليل!$C$3:$C$222,التحليل!$B$3:$B$222,$A20)) | H20: =COUNTIFS(التحليل!$B$3:$B$222,$A20,التحليل!$C$3:$C$222,">="&$B$6) -> 0 | I20: =IFERROR($H20/$C20,"")
A21: 10/9 | B21: =COUNTIF(التحليل!$B$3:$B$222,$A21) -> 20 | C21: =COUNTIFS(التحليل!$B$3:$B$222,$A21,التحليل!$C$3:$C$222,">=0") -> 0 | D21: =IFERROR(AVERAGEIF(التحليل!$B$3:$B$222,$A21,التحليل!$C$3:$C$222),"") | E21: =IFERROR($D21/$B$5,"") | F21: =IF($C21=0,"",_xlfn.MAXIFS(التحليل!$C$3:$C$222,التحليل!$B$3:$B$222,$A21)) | G21: =IF($C21=0,"",_xlfn.MINIFS(التحليل!$C$3:$C$222,التحليل!$B$3:$B$222,$A21)) | H21: =COUNTIFS(التحليل!$B$3:$B$222,$A21,التحليل!$C$3:$C$222,">="&$B$6) -> 0 | I21: =IFERROR($H21/$C21,"")
A22: 10/10 | B22: =COUNTIF(التحليل!$B$3:$B$222,$A22) -> 23 | C22: =COUNTIFS(التحليل!$B$3:$B$222,$A22,التحليل!$C$3:$C$222,">=0") -> 0 | D22: =IFERROR(AVERAGEIF(التحليل!$B$3:$B$222,$A22,التحليل!$C$3:$C$222),"") | E22: =IFERROR($D22/$B$5,"") | F22: =IF($C22=0,"",_xlfn.MAXIFS(التحليل!$C$3:$C$222,التحليل!$B$3:$B$222,$A22)) | G22: =IF($C22=0,"",_xlfn.MINIFS(التحليل!$C$3:$C$222,التحليل!$B$3:$B$222,$A22)) | H22: =COUNTIFS(التحليل!$B$3:$B$222,$A22,التحليل!$C$3:$C$222,">="&$B$6) -> 0 | I22: =IFERROR($H22/$C22,"")
A23: 10/ESE | B23: =COUNTIF(التحليل!$B$3:$B$222,$A23) -> 6 | C23: =COUNTIFS(التحليل!$B$3:$B$222,$A23,التحليل!$C$3:$C$222,">=0") -> 0 | D23: =IFERROR(AVERAGEIF(التحليل!$B$3:$B$222,$A23,التحليل!$C$3:$C$222),"") | E23: =IFERROR($D23/$B$5,"") | F23: =IF($C23=0,"",_xlfn.MAXIFS(التحليل!$C$3:$C$222,التحليل!$B$3:$B$222,$A23)) | G23: =IF($C23=0,"",_xlfn.MINIFS(التحليل!$C$3:$C$222,التحليل!$B$3:$B$222,$A23)) | H23: =COUNTIFS(التحليل!$B$3:$B$222,$A23,التحليل!$C$3:$C$222,">="&$B$6) -> 0 | I23: =IFERROR($H23/$C23,"")
A24: الإجمالي | B24: =SUM(B13:B23) -> 220 | C24: =SUM(C13:C23) -> 0 | D24: =IFERROR($C$10,"") | E24: =IFERROR($D$10,"") | F24: =IFERROR($E$10,"") -> 0 | G24: =IFERROR($F$10,"") -> 0 | H24: =SUM(H13:H23) -> 0 | I24: =IFERROR($H$10,"")
A26: النتائج حسب المهارة
A27: المهارة | B27: عدد الأسئلة | C27: الدرجة الكلية | D27: متوسط الإتقان | E27: عدد المتقنين | F27: نسبة المتقنين | G27: أعلى نسبة | H27: أدنى نسبة | I27: الترتيب (1=الأضعف)
A28: =IF(المهارات!$A2="","",المهارات!$A2) | B28: =IF($A28="","",COUNTIF(المهارات!$F$2:$F$24,$A28)) | C28: =IF($A28="","",SUMIF(المهارات!$F$2:$F$24,$A28,المهارات!$G$2:$G$24)) | D28: =IF($A28="","",IFERROR(AVERAGE(التحليل!D$3:D$222),"")) | E28: =IF($A28="","",COUNTIF(التحليل!D$3:D$222,">="&$B$4)) | F28: =IF(OR($A28="",$B$10=0),"",$E28/$B$10) | G28: =IF($A28="","",IFERROR(MAX(التحليل!D$3:D$222),"")) | H28: =IF($A28="","",IFERROR(MIN(التحليل!D$3:D$222),"")) | I28: =IF(OR($A28="",$D28=""),"",RANK($D28,$D$28:$D$46,1))
A29: =IF(المهارات!$A3="","",المهارات!$A3) | B29: =IF($A29="","",COUNTIF(المهارات!$F$2:$F$24,$A29)) | C29: =IF($A29="","",SUMIF(المهارات!$F$2:$F$24,$A29,المهارات!$G$2:$G$24)) | D29: =IF($A29="","",IFERROR(AVERAGE(التحليل!E$3:E$222),"")) | E29: =IF($A29="","",COUNTIF(التحليل!E$3:E$222,">="&$B$4)) | F29: =IF(OR($A29="",$B$10=0),"",$E29/$B$10) | G29: =IF($A29="","",IFERROR(MAX(التحليل!E$3:E$222),"")) | H29: =IF($A29="","",IFERROR(MIN(التحليل!E$3:E$222),"")) | I29: =IF(OR($A29="",$D29=""),"",RANK($D29,$D$28:$D$46,1))
A30: =IF(المهارات!$A4="","",المهارات!$A4) | B30: =IF($A30="","",COUNTIF(المهارات!$F$2:$F$24,$A30)) | C30: =IF($A30="","",SUMIF(المهارات!$F$2:$F$24,$A30,المهارات!$G$2:$G$24)) | D30: =IF($A30="","",IFERROR(AVERAGE(التحليل!F$3:F$222),"")) | E30: =IF($A30="","",COUNTIF(التحليل!F$3:F$222,">="&$B$4)) | F30: =IF(OR($A30="",$B$10=0),"",$E30/$B$10) | G30: =IF($A30="","",IFERROR(MAX(التحليل!F$3:F$222),"")) | H30: =IF($A30="","",IFERROR(MIN(التحليل!F$3:F$222),"")) | I30: =IF(OR($A30="",$D30=""),"",RANK($D30,$D$28:$D$46,1))
A31: =IF(المهارات!$A5="","",المهارات!$A5) | B31: =IF($A31="","",COUNTIF(المهارات!$F$2:$F$24,$A31)) | C31: =IF($A31="","",SUMIF(المهارات!$F$2:$F$24,$A31,المهارات!$G$2:$G$24)) | D31: =IF($A31="","",IFERROR(AVERAGE(التحليل!G$3:G$222),"")) | E31: =IF($A31="","",COUNTIF(التحليل!G$3:G$222,">="&$B$4)) | F31: =IF(OR($A31="",$B$10=0),"",$E31/$B$10) | G31: =IF($A31="","",IFERROR(MAX(التحليل!G$3:G$222),"")) | H31: =IF($A31="","",IFERROR(MIN(التحليل!G$3:G$222),"")) | I31: =IF(OR($A31="",$D31=""),"",RANK($D31,$D$28:$D$46,1))
A32: =IF(المهارات!$A6="","",المهارات!$A6) | B32: =IF($A32="","",COUNTIF(المهارات!$F$2:$F$24,$A32)) | C32: =IF($A32="","",SUMIF(المهارات!$F$2:$F$24,$A32,المهارات!$G$2:$G$24)) | D32: =IF($A32="","",IFERROR(AVERAGE(التحليل!H$3:H$222),"")) | E32: =IF($A32="","",COUNTIF(التحليل!H$3:H$222,">="&$B$4)) | F32: =IF(OR($A32="",$B$10=0),"",$E32/$B$10) | G32: =IF($A32="","",IFERROR(MAX(التحليل!H$3:H$222),"")) | H32: =IF($A32="","",IFERROR(MIN(التحليل!H$3:H$222),"")) | I32: =IF(OR($A32="",$D32=""),"",RANK($D32,$D$28:$D$46,1))
A33: =IF(المهارات!$A7="","",المهارات!$A7) | B33: =IF($A33="","",COUNTIF(المهارات!$F$2:$F$24,$A33)) | C33: =IF($A33="","",SUMIF(المهارات!$F$2:$F$24,$A33,المهارات!$G$2:$G$24)) | D33: =IF($A33="","",IFERROR(AVERAGE(التحليل!I$3:I$222),"")) | E33: =IF($A33="","",COUNTIF(التحليل!I$3:I$222,">="&$B$4)) | F33: =IF(OR($A33="",$B$10=0),"",$E33/$B$10) | G33: =IF($A33="","",IFERROR(MAX(التحليل!I$3:I$222),"")) | H33: =IF($A33="","",IFERROR(MIN(التحليل!I$3:I$222),"")) | I33: =IF(OR($A33="",$D33=""),"",RANK($D33,$D$28:$D$46,1))
A34: =IF(المهارات!$A8="","",المهارات!$A8) | B34: =IF($A34="","",COUNTIF(المهارات!$F$2:$F$24,$A34)) | C34: =IF($A34="","",SUMIF(المهارات!$F$2:$F$24,$A34,المهارات!$G$2:$G$24)) | D34: =IF($A34="","",IFERROR(AVERAGE(التحليل!J$3:J$222),"")) | E34: =IF($A34="","",COUNTIF(التحليل!J$3:J$222,">="&$B$4)) | F34: =IF(OR($A34="",$B$10=0),"",$E34/$B$10) | G34: =IF($A34="","",IFERROR(MAX(التحليل!J$3:J$222),"")) | H34: =IF($A34="","",IFERROR(MIN(التحليل!J$3:J$222),"")) | I34: =IF(OR($A34="",$D34=""),"",RANK($D34,$D$28:$D$46,1))
A35: =IF(المهارات!$A9="","",المهارات!$A9) | B35: =IF($A35="","",COUNTIF(المهارات!$F$2:$F$24,$A35)) | C35: =IF($A35="","",SUMIF(المهارات!$F$2:$F$24,$A35,المهارات!$G$2:$G$24)) | D35: =IF($A35="","",IFERROR(AVERAGE(التحليل!K$3:K$222),"")) | E35: =IF($A35="","",COUNTIF(التحليل!K$3:K$222,">="&$B$4)) | F35: =IF(OR($A35="",$B$10=0),"",$E35/$B$10) | G35: =IF($A35="","",IFERROR(MAX(التحليل!K$3:K$222),"")) | H35: =IF($A35="","",IFERROR(MIN(التحليل!K$3:K$222),"")) | I35: =IF(OR($A35="",$D35=""),"",RANK($D35,$D$28:$D$46,1))
A36: =IF(المهارات!$A10="","",المهارات!$A10) | B36: =IF($A36="","",COUNTIF(المهارات!$F$2:$F$24,$A36)) | C36: =IF($A36="","",SUMIF(المهارات!$F$2:$F$24,$A36,المهارات!$G$2:$G$24)) | D36: =IF($A36="","",IFERROR(AVERAGE(التحليل!L$3:L$222),"")) | E36: =IF($A36="","",COUNTIF(التحليل!L$3:L$222,">="&$B$4)) | F36: =IF(OR($A36="",$B$10=0),"",$E36/$B$10) | G36: =IF($A36="","",IFERROR(MAX(التحليل!L$3:L$222),"")) | H36: =IF($A36="","",IFERROR(MIN(التحليل!L$3:L$222),"")) | I36: =IF(OR($A36="",$D36=""),"",RANK($D36,$D$28:$D$46,1))
A37: =IF(المهارات!$A11="","",المهارات!$A11) | B37: =IF($A37="","",COUNTIF(المهارات!$F$2:$F$24,$A37)) | C37: =IF($A37="","",SUMIF(المهارات!$F$2:$F$24,$A37,المهارات!$G$2:$G$24)) | D37: =IF($A37="","",IFERROR(AVERAGE(التحليل!M$3:M$222),"")) | E37: =IF($A37="","",COUNTIF(التحليل!M$3:M$222,">="&$B$4)) | F37: =IF(OR($A37="",$B$10=0),"",$E37/$B$10) | G37: =IF($A37="","",IFERROR(MAX(التحليل!M$3:M$222),"")) | H37: =IF($A37="","",IFERROR(MIN(التحليل!M$3:M$222),"")) | I37: =IF(OR($A37="",$D37=""),"",RANK($D37,$D$28:$D$46,1))
A38: =IF(المهارات!$A12="","",المهارات!$A12) | B38: =IF($A38="","",COUNTIF(المهارات!$F$2:$F$24,$A38)) | C38: =IF($A38="","",SUMIF(المهارات!$F$2:$F$24,$A38,المهارات!$G$2:$G$24)) | D38: =IF($A38="","",IFERROR(AVERAGE(التحليل!N$3:N$222),"")) | E38: =IF($A38="","",COUNTIF(التحليل!N$3:N$222,">="&$B$4)) | F38: =IF(OR($A38="",$B$10=0),"",$E38/$B$10) | G38: =IF($A38="","",IFERROR(MAX(التحليل!N$3:N$222),"")) | H38: =IF($A38="","",IFERROR(MIN(التحليل!N$3:N$222),"")) | I38: =IF(OR($A38="",$D38=""),"",RANK($D38,$D$28:$D$46,1))
A39: =IF(المهارات!$A13="","",المهارات!$A13) | B39: =IF($A39="","",COUNTIF(المهارات!$F$2:$F$24,$A39)) | C39: =IF($A39="","",SUMIF(المهارات!$F$2:$F$24,$A39,المهارات!$G$2:$G$24)) | D39: =IF($A39="","",IFERROR(AVERAGE(التحليل!O$3:O$222),"")) | E39: =IF($A39="","",COUNTIF(التحليل!O$3:O$222,">="&$B$4)) | F39: =IF(OR($A39="",$B$10=0),"",$E39/$B$10) | G39: =IF($A39="","",IFERROR(MAX(التحليل!O$3:O$222),"")) | H39: =IF($A39="","",IFERROR(MIN(التحليل!O$3:O$222),"")) | I39: =IF(OR($A39="",$D39=""),"",RANK($D39,$D$28:$D$46,1))
A40: =IF(المهارات!$A14="","",المهارات!$A14) | B40: =IF($A40="","",COUNTIF(المهارات!$F$2:$F$24,$A40)) | C40: =IF($A40="","",SUMIF(المهارات!$F$2:$F$24,$A40,المهارات!$G$2:$G$24)) | D40: =IF($A40="","",IFERROR(AVERAGE(التحليل!P$3:P$222),"")) | E40: =IF($A40="","",COUNTIF(التحليل!P$3:P$222,">="&$B$4)) | F40: =IF(OR($A40="",$B$10=0),"",$E40/$B$10) | G40: =IF($A40="","",IFERROR(MAX(التحليل!P$3:P$222),"")) | H40: =IF($A40="","",IFERROR(MIN(التحليل!P$3:P$222),"")) | I40: =IF(OR($A40="",$D40=""),"",RANK($D40,$D$28:$D$46,1))
A41: =IF(المهارات!$A15="","",المهارات!$A15) | B41: =IF($A41="","",COUNTIF(المهارات!$F$2:$F$24,$A41)) | C41: =IF($A41="","",SUMIF(المهارات!$F$2:$F$24,$A41,المهارات!$G$2:$G$24)) | D41: =IF($A41="","",IFERROR(AVERAGE(التحليل!Q$3:Q$222),"")) | E41: =IF($A41="","",COUNTIF(التحليل!Q$3:Q$222,">="&$B$4)) | F41: =IF(OR($A41="",$B$10=0),"",$E41/$B$10) | G41: =IF($A41="","",IFERROR(MAX(التحليل!Q$3:Q$222),"")) | H41: =IF($A41="","",IFERROR(MIN(التحليل!Q$3:Q$222),"")) | I41: =IF(OR($A41="",$D41=""),"",RANK($D41,$D$28:$D$46,1))
A42: =IF(المهارات!$A16="","",المهارات!$A16) | B42: =IF($A42="","",COUNTIF(المهارات!$F$2:$F$24,$A42)) | C42: =IF($A42="","",SUMIF(المهارات!$F$2:$F$24,$A42,المهارات!$G$2:$G$24)) | D42: =IF($A42="","",IFERROR(AVERAGE(التحليل!R$3:R$222),"")) | E42: =IF($A42="","",COUNTIF(التحليل!R$3:R$222,">="&$B$4)) | F42: =IF(OR($A42="",$B$10=0),"",$E42/$B$10) | G42: =IF($A42="","",IFERROR(MAX(التحليل!R$3:R$222),"")) | H42: =IF($A42="","",IFERROR(MIN(التحليل!R$3:R$222),"")) | I42: =IF(OR($A42="",$D42=""),"",RANK($D42,$D$28:$D$46,1))
A43: =IF(المهارات!$A17="","",المهارات!$A17) | B43: =IF($A43="","",COUNTIF(المهارات!$F$2:$F$24,$A43)) | C43: =IF($A43="","",SUMIF(المهارات!$F$2:$F$24,$A43,المهارات!$G$2:$G$24)) | D43: =IF($A43="","",IFERROR(AVERAGE(التحليل!S$3:S$222),"")) | E43: =IF($A43="","",COUNTIF(التحليل!S$3:S$222,">="&$B$4)) | F43: =IF(OR($A43="",$B$10=0),"",$E43/$B$10) | G43: =IF($A43="","",IFERROR(MAX(التحليل!S$3:S$222),"")) | H43: =IF($A43="","",IFERROR(MIN(التحليل!S$3:S$222),"")) | I43: =IF(OR($A43="",$D43=""),"",RANK($D43,$D$28:$D$46,1))
...

Sheet المهارات
A1: قائمة المهارات | B1: أدخل قائمة المهارات المطلوب تحليلها في الجدول المجاور | E1: السؤال | F1: المهارة | G1: الدرجة الكلية | J1: الفصول
E2: 1 | J2: 10/1
E3: 2 | J3: 10/2
E4: 3 | J4: 10/3
E5: 4 | J5: 10/4
E6: 5 | J6: 10/5
E7: 6 | J7: 10/6
E8: 7 | J8: 10/7
E9: 8 | J9: 10/8
E10: 9 | J10: 10/9
E11: 10 | J11: 10/10
E12: 11 | J12: 10/ESE
E13: 12
E14: 13
E15: 14
E16: 15
E17: 16
E18: 17
E19: 18
E20: 19
E21: 20
E22: 21
E23: 22
E24: 23
E26: فحص الجاهزية
E27: مجموع الدرجات الكلية للاختبار | G27: =SUM(G2:G24) -> 0
E28: عدد الأسئلة المرتبطة بمهارة | G28: =SUMPRODUCT((E2:E24<>"")*(F2:F24<>"")) -> 0
E29: أسئلة بلا مهارة (يجب أن تكون 0) | G29: =SUMPRODUCT((E2:E24<>"")*(F2:F24="")) -> 23
E30: أسئلة بلا درجة كلية (يجب أن تكون 0) | G30: =SUMPRODUCT((E2:E24<>"")*(G2:G24="")) -> 23
E31: الخلايا الصفراء هي خلايا الإدخال: اكتب المهارات في العمود (قائمة المهارات)، ثم اربط كل سؤال بمهارة واكتب درجته الكلية.

Sheet الرصد
A1: اسم الطالب | B1: الصف | C1: الأسئلة | AA1: مجموع درجات الطالب
C2: =المهارات!E2 -> 1 | D2: =المهارات!E3 -> 2 | E2: =المهارات!E4 -> 3 | F2: =المهارات!E5 -> 4 | G2: =المهارات!E6 -> 5 | H2: =المهارات!E7 -> 6 | I2: =المهارات!E8 -> 7 | J2: =المهارات!E9 -> 8 | K2: =المهارات!E10 -> 9 | L2: =المهارات!E11 -> 10 | M2: =المهارات!E12 -> 11 | N2: =المهارات!E13 -> 12 | O2: =المهارات!E14 -> 13 | P2: =المهارات!E15 -> 14 | Q2: =المهارات!E16 -> 15 | R2: =المهارات!E17 -> 16 | S2: =المهارات!E18 -> 17 | T2: =المهارات!E19 -> 18 | U2: =المهارات!E20 -> 19 | V2: =المهارات!E21 -> 20 | W2: =المهارات!E22 -> 21 | X2: =المهارات!E23 -> 22 | Y2: =المهارات!E24 -> 23
A3: احمد عمر سعيد صالح الحسن | B3: 10/1 | AA3: =IF(COUNT(C3:Y3)=0,"",SUM(C3:Y3))
A4: بكر الخلف | B4: 10/1 | AA4: =IF(COUNT(C4:Y4)=0,"",SUM(C4:Y4))
A5: تميم عبدالعزيز عثمان بخيت الغانم | B5: 10/1 | AA5: =IF(COUNT(C5:Y5)=0,"",SUM(C5:Y5))
A6: جابر حمد جابر ذروه البريد | B6: 10/1 | AA6: =IF(COUNT(C6:Y6)=0,"",SUM(C6:Y6))
A7: جاسم جابر جاسم الشقيرى المهندى | B7: 10/1 | AA7: =IF(COUNT(C7:Y7)=0,"",SUM(C7:Y7))
A8: جاسم محمد مبارك لملوم المسيفرى | B8: 10/1 | AA8: =IF(COUNT(C8:Y8)=0,"",SUM(C8:Y8))
A9: جاسم محمد ناصر البوعفره الكوارى | B9: 10/1 | AA9: =IF(COUNT(C9:Y9)=0,"",SUM(C9:Y9))
A10: حمد خالد حسان نصر الحجيلي | B10: 10/1 | AA10: =IF(COUNT(C10:Y10)=0,"",SUM(C10:Y10))
A11: حمد عيد عبدالكريم عيد الجاسم | B11: 10/1 | AA11: =IF(COUNT(C11:Y11)=0,"",SUM(C11:Y11))
A12: سعود عثمان مرزوق فرج العبدالله | B12: 10/1 | AA12: =IF(COUNT(C12:Y12)=0,"",SUM(C12:Y12))
A13: سيف بطى سيف البطى الكعبى | B13: 10/1 | AA13: =IF(COUNT(C13:Y13)=0,"",SUM(C13:Y13))
A14: عبدالرحمن مبارك حسن بدو العبدالله | B14: 10/1 | AA14: =IF(COUNT(C14:Y14)=0,"",SUM(C14:Y14))
... A222: يوسف امين مروان امين نزال | B222: 10/ESE | AA222: =IF(COUNT(C222:Y222)=0,"",SUM(C222:Y222))

Sheet التحليل
A1: اسم الطالب | B1: الصف | C1: الدرجة | D1: التحليل حسب المهارات | W1: النسبة المئوية | X1: النسب المئوية في أعمدة المهارات تُحسب آليًا من ورقة (المهارات) و(الرصد).
D2: =IF(المهارات!$A2="","",المهارات!$A2) | E2: =IF(المهارات!$A3="","",المهارات!$A3) | F2: =IF(المهارات!$A4="","",المهارات!$A4) | G2: =IF(المهارات!$A5="","",المهارات!$A5) | H2: =IF(المهارات!$A6="","",المهارات!$A6) | I2: =IF(المهارات!$A7="","",المهارات!$A7) | J2: =IF(المهارات!$A8="","",المهارات!$A8) | K2: =IF(المهارات!$A9="","",المهارات!$A9) | L2: =IF(المهارات!$A10="","",المهارات!$A10) | M2: =IF(المهارات!$A11="","",المهارات!$A11) | N2: =IF(المهارات!$A12="","",المهارات!$A12) | O2: =IF(المهارات!$A13="","",المهارات!$A13) | P2: =IF(المهارات!$A14="","",المهارات!$A14) | Q2: =IF(المهارات!$A15="","",المهارات!$A15) | R2: =IF(المهارات!$A16="","",المهارات!$A16) | S2: =IF(المهارات!$A17="","",المهارات!$A17) | T2: =IF(المهارات!$A18="","",المهارات!$A18) | U2: =IF(المهارات!$A19="","",المهارات!$A19) | V2: =IF(المهارات!$A20="","",المهارات!$A20)
A3: احمد عمر سعيد صالح الحسن | B3: 10/1 | C3: =IF(COUNT(الرصد!C3:Y3)=0,"",SUM(الرصد!C3:Y3)) | D3: =IF(OR(D$2="",COUNT(الرصد!$C3:$Y3)=0),"",IFERROR(SUMIF(معالجة!$B$3:$X$3,D$2,الرصد!$C3:$Y3)/SUMIF(معالجة!$B$3:$X$3,D$2,معالجة!$B$4:$X$4),"")) | E3: =IF(OR(E$2="",COUNT(الرصد!$C3:$Y3)=0),"",IFERROR(SUMIF(معالجة!$B$3:$X$3,E$2,الرصد!$C3:$Y3)/SUMIF(معالجة!$B$3:$X$3,E$2,معالجة!$B$4:$X$4),"")) | F3: =IF(OR(F$2="",COUNT(الرصد!$C3:$Y3)=0),"",IFERROR(SUMIF(معالجة!$B$3:$X$3,F$2,الرصد!$C3:$Y3)/SUMIF(معالجة!$B$3:$X$3,F$2,معالجة!$B$4:$X$4),"")) | G3: =IF(OR(G$2="",COUNT(الرصد!$C3:$Y3)=0),"",IFERROR(SUMIF(معالجة!$B$3:$X$3,G$2,الرصد!$C3:$Y3)/SUMIF(معالجة!$B$3:$X$3,G$2,معالجة!$B$4:$X$4),"")) | H3: =IF(OR(H$2="",COUNT(الرصد!$C3:$Y3)=0),"",IFERROR(SUMIF(معالجة!$B$3:$X$3,H$2,الرصد!$C3:$Y3)/SUMIF(معالجة!$B$3:$X$3,H$2,معالجة!$B$4:$X$4),"")) | I3: =IF(OR(I$2="",COUNT(الرصد!$C3:$Y3)=0),"",IFERROR(SUMIF(معالجة!$B$3:$X$3,I$2,الرصد!$C3:$Y3)/SUMIF(معالجة!$B$3:$X$3,I$2,معالجة!$B$4:$X$4),"")) | J3: =IF(OR(J$2="",COUNT(الرصد!$C3:$Y3)=0),"",IFERROR(SUMIF(معالجة!$B$3:$X$3,J$2,الرصد!$C3:$Y3)/SUMIF(معالجة!$B$3:$X$3,J$2,معالجة!$B$4:$X$4),"")) | K3: =IF(OR(K$2="",COUNT(الرصد!$C3:$Y3)=0),"",IFERROR(SUMIF(معالجة!$B$3:$X$3,K$2,الرصد!$C3:$Y3)/SUMIF(معالجة!$B$3:$X$3,K$2,معالجة!$B$4:$X$4),"")) | ... V3: =IF(OR(V$2="",COUNT(الرصد!$C3:$Y3)=0),"",IFERROR(SUMIF(معالجة!$B$3:$X$3,V$2,الرصد!$C3:$Y3)/SUMIF(معالجة!$B$3:$X$3,V$2,معالجة!$B$4:$X$4),"")) | W3: =IFERROR(C3/المهارات!$G$27,"")
A4: بكر الخلف | B4: 10/1 | C4: =IF(COUNT(الرصد!C4:Y4)=0,"",SUM(الرصد!C4:Y4)) | D4: =IF(OR(D$2="",COUNT(الرصد!$C4:$Y4)=0),"",IFERROR(SUMIF(معالجة!$B$3:$X$3,D$2,الرصد!$C4:$Y4)/SUMIF(معالجة!$B$3:$X$3,D$2,معالجة!$B$4:$X$4),"")) | E4: =IF(OR(E$2="",COUNT(الرصد!$C4:$Y4)=0),"",IFERROR(SUMIF(معالجة!$B$3:$X$3,E$2,الرصد!$C4:$Y4)/SUMIF(معالجة!$B$3:$X$3,E$2,معالجة!$B$4:$X$4),"")) | F4: =IF(OR(F$2="",COUNT(الرصد!$C4:$Y4)=0),"",IFERROR(SUMIF(معالجة!$B$3:$X$3,F$2,الرصد!$C4:$Y4)/SUMIF(معالجة!$B$3:$X$3,F$2,معالجة!$B$4:$X$4),"")) | G4: =IF(OR(G$2="",COUNT(الرصد!$C4:$Y4)=0),"",IFERROR(SUMIF(معالجة!$B$3:$X$3,G$2,الرصد!$C4:$Y4)/SUMIF(معالجة!$B$3:$X$3,G$2,معالجة!$B$4:$X$4),"")) | H4: =IF(OR(H$2="",COUNT(الرصد!$C4:$Y4)=0),"",IFERROR(SUMIF(معالجة!$B$3:$X$3,H$2,الرصد!$C4:$Y4)/SUMIF(معالجة!$B$3:$X$3,H$2,معالجة!$B$4:$X$4),"")) | I4: =IF(OR(I$2="",COUNT(الرصد!$C4:$Y4)=0),"",IFERROR(SUMIF(معالجة!$B$3:$X$3,I$2,الرصد!$C4:$Y4)/SUMIF(معالجة!$B$3:$X$3,I$2,معالجة!$B$4:$X$4),"")) | J4: =IF(OR(J$2="",COUNT(الرصد!$C4:$Y4)=0),"",IFERROR(SUMIF(معالجة!$B$3:$X$3,J$2,الرصد!$C4:$Y4)/SUMIF(معالجة!$B$3:$X$3,J$2,معالجة!$B$4:$X$4),"")) | K4: =IF(OR(K$2="",COUNT(الرصد!$C4:$Y4)=0),"",IFERROR(SUMIF(معالجة!$B$3:$X$3,K$2,الرصد!$C4:$Y4)/SUMIF(معالجة!$B$3:$X$3,K$2,معالجة!$B$4:$X$4),"")) | ... V4: =IF(OR(V$2="",COUNT(الرصد!$C4:$Y4)=0),"",IFERROR(SUMIF(معالجة!$B$3:$X$3,V$2,الرصد!$C4:$Y4)/SUMIF(معالجة!$B$3:$X$3,V$2,معالجة!$B$4:$X$4),"")) | W4: =IFERROR(C4/المهارات!$G$27,"")
A5: تميم عبدالعزيز عثمان بخيت الغانم | B5: 10/1 | C5: =IF(COUNT(الرصد!C5:Y5)=0,"",SUM(الرصد!C5:Y5)) | D5: =IF(OR(D$2="",COUNT(الرصد!$C5:$Y5)=0),"",IFERROR(SUMIF(معالجة!$B$3:$X$3,D$2,الرصد!$C5:$Y5)/SUMIF(معالجة!$B$3:$X$3,D$2,معالجة!$B$4:$X$4),"")) | E5: =IF(OR(E$2="",COUNT(الرصد!$C5:$Y5)=0),"",IFERROR(SUMIF(معالجة!$B$3:$X$3,E$2,الرصد!$C5:$Y5)/SUMIF(معالجة!$B$3:$X$3,E$2,معالجة!$B$4:$X$4),"")) | F5: =IF(OR(F$2="",COUNT(الرصد!$C5:$Y5)=0),"",IFERROR(SUMIF(معالجة!$B$3:$X$3,F$2,الرصد!$C5:$Y5)/SUMIF(معالجة!$B$3:$X$3,F$2,معالجة!$B$4:$X$4),"")) | G5: =IF(OR(G$2="",COUNT(الرصد!$C5:$Y5)=0),"",IFERROR(SUMIF(معالجة!$B$3:$X$3,G$2,الرصد!$C5:$Y5)/SUMIF(معالجة!$B$3:$X$3,G$2,معالجة!$B$4:$X$4),"")) | H5: =IF(OR(H$2="",COUNT(الرصد!$C5:$Y5)=0),"",IFERROR(SUMIF(معالجة!$B$3:$X$3,H$2,الرصد!$C5:$Y5)/SUMIF(معالجة!$B$3:$X$3,H$2,معالجة!$B$4:$X$4),"")) | I5: =IF(OR(I$2="",COUNT(الرصد!$C5:$Y5)=0),"",IFERROR(SUMIF(معالجة!$B$3:$X$3,I$2,الرصد!$C5:$Y5)/SUMIF(معالجة!$B$3:$X$3,I$2,معالجة!$B$4:$X$4),"")) | J5: =IF(OR(J$2="",COUNT(الرصد!$C5:$Y5)=0),"",IFERROR(SUMIF(معالجة!$B$3:$X$3,J$2,الرصد!$C5:$Y5)/SUMIF(معالجة!$B$3:$X$3,J$2,معالجة!$B$4:$X$4),"")) | K5: =IF(OR(K$2="",COUNT(الرصد!$C5:$Y5)=0),"",IFERROR(SUMIF(معالجة!$B$3:$X$3,K$2,الرصد!$C5:$Y5)/SUMIF(معالجة!$B$3:$X$3,K$2,معالجة!$B$4:$X$4),"")) | ... V5: =IF(OR(V$2="",COUNT(الرصد!$C5:$Y5)=0),"",IFERROR(SUMIF(معالجة!$B$3:$X$3,V$2,الرصد!$C5:$Y5)/SUMIF(معالجة!$B$3:$X$3,V$2,معالجة!$B$4:$X$4),"")) | W5: =IFERROR(C5/المهارات!$G$27,"")
A6: جابر حمد جابر ذروه البريد | B6: 10/1 | C6: =IF(COUNT(الرصد!C6:Y6)=0,"",SUM(الرصد!C6:Y6)) | D6: =IF(OR(D$2="",COUNT(الرصد!$C6:$Y6)=0),"",IFERROR(SUMIF(معالجة!$B$3:$X$3,D$2,الرصد!$C6:$Y6)/SUMIF(معالجة!$B$3:$X$3,D$2,معالجة!$B$4:$X$4),"")) | E6: =IF(OR(E$2="",COUNT(الرصد!$C6:$Y6)=0),"",IFERROR(SUMIF(معالجة!$B$3:$X$3,E$2,الرصد!$C6:$Y6)/SUMIF(معالجة!$B$3:$X$3,E$2,معالجة!$B$4:$X$4),"")) | F6: =IF(OR(F$2="",COUNT(الرصد!$C6:$Y6)=0),"",IFERROR(SUMIF(معالجة!$B$3:$X$3,F$2,الرصد!$C6:$Y6)/SUMIF(معالجة!$B$3:$X$3,F$2,معالجة!$B$4:$X$4),"")) | G6: =IF(OR(G$2="",COUNT(الرصد!$C6:$Y6)=0),"",IFERROR(SUMIF(معالجة!$B$3:$X$3,G$2,الرصد!$C6:$Y6)/SUMIF(معالجة!$B$3:$X$3,G$2,معالجة!$B$4:$X$4),"")) | H6: =IF(OR(H$2="",COUNT(الرصد!$C6:$Y6)=0),"",IFERROR(SUMIF(معالجة!$B$3:$X$3,H$2,الرصد!$C6:$Y6)/SUMIF(معالجة!$B$3:$X$3,H$2,معالجة!$B$4:$X$4),"")) | I6: =IF(OR(I$2="",COUNT(الرصد!$C6:$Y6)=0),"",IFERROR(SUMIF(معالجة!$B$3:$X$3,I$2,الرصد!$C6:$Y6)/SUMIF(معالجة!$B$3:$X$3,I$2,معالجة!$B$4:$X$4),"")) | J6: =IF(OR(J$2="",COUNT(الرصد!$C6:$Y6)=0),"",IFERROR(SUMIF(معالجة!$B$3:$X$3,J$2,الرصد!$C6:$Y6)/SUMIF(معالجة!$B$3:$X$3,J$2,معالجة!$B$4:$X$4),"")) | K6: =IF(OR(K$2="",COUNT(الرصد!$C6:$Y6)=0),"",IFERROR(SUMIF(معالجة!$B$3:$X$3,K$2,الرصد!$C6:$Y6)/SUMIF(معالجة!$B$3:$X$3,K$2,معالجة!$B$4:$X$4),"")) | ... V6: =IF(OR(V$2="",COUNT(الرصد!$C6:$Y6)=0),"",IFERROR(SUMIF(معالجة!$B$3:$X$3,V$2,الرصد!$C6:$Y6)/SUMIF(معالجة!$B$3:$X$3,V$2,معالجة!$B$4:$X$4),"")) | W6: =IFERROR(C6/المهارات!$G$27,"")
A7: جاسم جابر جاسم الشقيرى المهندى | B7: 10/1 | C7: =IF(COUNT(الرصد!C7:Y7)=0,"",SUM(الرصد!C7:Y7)) | D7: =IF(OR(D$2="",COUNT(الرصد!$C7:$Y7)=0),"",IFERROR(SUMIF(معالجة!$B$3:$X$3,D$2,الرصد!$C7:$Y7)/SUMIF(معالجة!$B$3:$X$3,D$2,معالجة!$B$4:$X$4),"")) | E7: =IF(OR(E$2="",COUNT(الرصد!$C7:$Y7)=0),"",IFERROR(SUMIF(معالجة!$B$3:$X$3,E$2,الرصد!$C7:$Y7)/SUMIF(معالجة!$B$3:$X$3,E$2,معالجة!$B$4:$X$4),"")) | F7: =IF(OR(F$2="",COUNT(الرصد!$C7:$Y7)=0),"",IFERROR(SUMIF(معالجة!$B$3:$X$3,F$2,الرصد!$C7:$Y7)/SUMIF(معالجة!$B$3:$X$3,F$2,معالجة!$B$4:$X$4),"")) | G7: =IF(OR(G$2="",COUNT(الرصد!$C7:$Y7)=0),"",IFERROR(SUMIF(معالجة!$B$3:$X$3,G$2,الرصد!$C7:$Y7)/SUMIF(معالجة!$B$3:$X$3,G$2,معالجة!$B$4:$X$4),"")) | H7: =IF(OR(H$2="",COUNT(الرصد!$C7:$Y7)=0),"",IFERROR(SUMIF(معالجة!$B$3:$X$3,H$2,الرصد!$C7:$Y7)/SUMIF(معالجة!$B$3:$X$3,H$2,معالجة!$B$4:$X$4),"")) | I7: =IF(OR(I$2="",COUNT(الرصد!$C7:$Y7)=0),"",IFERROR(SUMIF(معالجة!$B$3:$X$3,I$2,الرصد!$C7:$Y7)/SUMIF(معالجة!$B$3:$X$3,I$2,معالجة!$B$4:$X$4),"")) | J7: =IF(OR(J$2="",COUNT(الرصد!$C7:$Y7)=0),"",IFERROR(SUMIF(معالجة!$B$3:$X$3,J$2,الرصد!$C7:$Y7)/SUMIF(معالجة!$B$3:$X$3,J$2,معالجة!$B$4:$X$4),"")) | K7: =IF(OR(K$2="",COUNT(الرصد!$C7:$Y7)=0),"",IFERROR(SUMIF(معالجة!$B$3:$X$3,K$2,الرصد!$C7:$Y7)/SUMIF(معالجة!$B$3:$X$3,K$2,معالجة!$B$4:$X$4),"")) | ... V7: =IF(OR(V$2="",COUNT(الرصد!$C7:$Y7)=0),"",IFERROR(SUMIF(معالجة!$B$3:$X$3,V$2,الرصد!$C7:$Y7)/SUMIF(معالجة!$B$3:$X$3,V$2,معالجة!$B$4:$X$4),"")) | W7: =IFERROR(C7/المهارات!$G$27,"")
A8: جاسم محمد مبارك لملوم المسيفرى | B8: 10/1 | C8: =IF(COUNT(الرصد!C8:Y8)=0,"",SUM(الرصد!C8:Y8)) | D8: =IF(OR(D$2="",COUNT(الرصد!$C8:$Y8)=0),"",IFERROR(SUMIF(معالجة!$B$3:$X$3,D$2,الرصد!$C8:$Y8)/SUMIF(معالجة!$B$3:$X$3,D$2,معالجة!$B$4:$X$4),"")) | E8: =IF(OR(E$2="",COUNT(الرصد!$C8:$Y8)=0),"",IFERROR(SUMIF(معالجة!$B$3:$X$3,E$2,الرصد!$C8:$Y8)/SUMIF(معالجة!$B$3:$X$3,E$2,معالجة!$B$4:$X$4),"")) | F8: =IF(OR(F$2="",COUNT(الرصد!$C8:$Y8)=0),"",IFERROR(SUMIF(معالجة!$B$3:$X$3,F$2,الرصد!$C8:$Y8)/SUMIF(معالجة!$B$3:$X$3,F$2,معالجة!$B$4:$X$4),"")) | G8: =IF(OR(G$2="",COUNT(الرصد!$C8:$Y8)=0),"",IFERROR(SUMIF(معالجة!$B$3:$X$3,G$2,الرصد!$C8:$Y8)/SUMIF(معالجة!$B$3:$X$3,G$2,معالجة!$B$4:$X$4),"")) | H8: =IF(OR(H$2="",COUNT(الرصد!$C8:$Y8)=0),"",IFERROR(SUMIF(معالجة!$B$3:$X$3,H$2,الرصد!$C8:$Y8)/SUMIF(معالجة!$B$3:$X$3,H$2,معالجة!$B$4:$X$4),"")) | I8: =IF(OR(I$2="",COUNT(الرصد!$C8:$Y8)=0),"",IFERROR(SUMIF(معالجة!$B$3:$X$3,I$2,الرصد!$C8:$Y8)/SUMIF(معالجة!$B$3:$X$3,I$2,معالجة!$B$4:$X$4),"")) | J8: =IF(OR(J$2="",COUNT(الرصد!$C8:$Y8)=0),"",IFERROR(SUMIF(معالجة!$B$3:$X$3,J$2,الرصد!$C8:$Y8)/SUMIF(معالجة!$B$3:$X$3,J$2,معالجة!$B$4:$X$4),"")) | K8: =IF(OR(K$2="",COUNT(الرصد!$C8:$Y8)=0),"",IFERROR(SUMIF(معالجة!$B$3:$X$3,K$2,الرصد!$C8:$Y8)/SUMIF(معالجة!$B$3:$X$3,K$2,معالجة!$B$4:$X$4),"")) | ... V8: =IF(OR(V$2="",COUNT(الرصد!$C8:$Y8)=0),"",IFERROR(SUMIF(معالجة!$B$3:$X$3,V$2,الرصد!$C8:$Y8)/SUMIF(معالجة!$B$3:$X$3,V$2,معالجة!$B$4:$X$4),"")) | W8: =IFERROR(C8/المهارات!$G$27,"")
A9: جاسم محمد ناصر البوعفره الكوارى | B9: 10/1 | C9: =IF(COUNT(الرصد!C9:Y9)=0,"",SUM(الرصد!C9:Y9)) | D9: =IF(OR(D$2="",COUNT(الرصد!$C9:$Y9)=0),"",IFERROR(SUMIF(معالجة!$B$3:$X$3,D$2,الرصد!$C9:$Y9)/SUMIF(معالجة!$B$3:$X$3,D$2,معالجة!$B$4:$X$4),"")) | E9: =IF(OR(E$2="",COUNT(الرصد!$C9:$Y9)=0),"",IFERROR(SUMIF(معالجة!$B$3:$X$3,E$2,الرصد!$C9:$Y9)/SUMIF(معالجة!$B$3:$X$3,E$2,معالجة!$B$4:$X$4),"")) | F9: =IF(OR(F$2="",COUNT(الرصد!$C9:$Y9)=0),"",IFERROR(SUMIF(معالجة!$B$3:$X$3,F$2,الرصد!$C9:$Y9)/SUMIF(معالجة!$B$3:$X$3,F$2,معالجة!$B$4:$X$4),"")) | G9: =IF(OR(G$2="",COUNT(الرصد!$C9:$Y9)=0),"",IFERROR(SUMIF(معالجة!$B$3:$X$3,G$2,الرصد!$C9:$Y9)/SUMIF(معالجة!$B$3:$X$3,G$2,معالجة!$B$4:$X$4),"")) | H9: =IF(OR(H$2="",COUNT(الرصد!$C9:$Y9)=0),"",IFERROR(SUMIF(معالجة!$B$3:$X$3,H$2,الرصد!$C9:$Y9)/SUMIF(معالجة!$B$3:$X$3,H$2,معالجة!$B$4:$X$4),"")) | I9: =IF(OR(I$2="",COUNT(الرصد!$C9:$Y9)=0),"",IFERROR(SUMIF(معالجة!$B$3:$X$3,I$2,الرصد!$C9:$Y9)/SUMIF(معالجة!$B$3:$X$3,I$2,معالجة!$B$4:$X$4),"")) | J9: =IF(OR(J$2="",COUNT(الرصد!$C9:$Y9)=0),"",IFERROR(SUMIF(معالجة!$B$3:$X$3,J$2,الرصد!$C9:$Y9)/SUMIF(معالجة!$B$3:$X$3,J$2,معالجة!$B$4:$X$4),"")) | K9: =IF(OR(K$2="",COUNT(الرصد!$C9:$Y9)=0),"",IFERROR(SUMIF(معالجة!$B$3:$X$3,K$2,الرصد!$C9:$Y9)/SUMIF(معالجة!$B$3:$X$3,K$2,معالجة!$B$4:$X$4),"")) | ... V9: =IF(OR(V$2="",COUNT(الرصد!$C9:$Y9)=0),"",IFERROR(SUMIF(معالجة!$B$3:$X$3,V$2,الرصد!$C9:$Y9)/SUMIF(معالجة!$B$3:$X$3,V$2,معالجة!$B$4:$X$4),"")) | W9: =IFERROR(C9/المهارات!$G$27,"")
A10: حمد خالد حسان نصر الحجيلي | B10: 10/1 | C10: =IF(COUNT(الرصد!C10:Y10)=0,"",SUM(الرصد!C10:Y10)) | D10: =IF(OR(D$2="",COUNT(الرصد!$C10:$Y10)=0),"",IFERROR(SUMIF(معالجة!$B$3:$X$3,D$2,الرصد!$C10:$Y10)/SUMIF(معالجة!$B$3:$X$3,D$2,معالجة!$B$4:$X$4),"")) | E10: =IF(OR(E$2="",COUNT(الرصد!$C10:$Y10)=0),"",IFERROR(SUMIF(معالجة!$B$3:$X$3,E$2,الرصد!$C10:$Y10)/SUMIF(معالجة!$B$3:$X$3,E$2,معالجة!$B$4:$X$4),"")) | F10: =IF(OR(F$2="",COUNT(الرصد!$C10:$Y10)=0),"",IFERROR(SUMIF(معالجة!$B$3:$X$3,F$2,الرصد!$C10:$Y10)/SUMIF(معالجة!$B$3:$X$3,F$2,معالجة!$B$4:$X$4),"")) | G10: =IF(OR(G$2="",COUNT(الرصد!$C10:$Y10)=0),"",IFERROR(SUMIF(معالجة!$B$3:$X$3,G$2,الرصد!$C10:$Y10)/SUMIF(معالجة!$B$3:$X$3,G$2,معالجة!$B$4:$X$4),"")) | H10: =IF(OR(H$2="",COUNT(الرصد!$C10:$Y10)=0),"",IFERROR(SUMIF(معالجة!$B$3:$X$3,H$2,الرصد!$C10:$Y10)/SUMIF(معالجة!$B$3:$X$3,H$2,معالجة!$B$4:$X$4),"")) | I10: =IF(OR(I$2="",COUNT(الرصد!$C10:$Y10)=0),"",IFERROR(SUMIF(معالجة!$B$3:$X$3,I$2,الرصد!$C10:$Y10)/SUMIF(معالجة!$B$3:$X$3,I$2,معالجة!$B$4:$X$4),"")) | J10: =IF(OR(J$2="",COUNT(الرصد!$C10:$Y10)=0),"",IFERROR(SUMIF(معالجة!$B$3:$X$3,J$2,الرصد!$C10:$Y10)/SUMIF(معالجة!$B$3:$X$3,J$2,معالجة!$B$4:$X$4),"")) | K10: =IF(OR(K$2="",COUNT(الرصد!$C10:$Y10)=0),"",IFERROR(SUMIF(معالجة!$B$3:$X$3,K$2,الرصد!$C10:$Y10)/SUMIF(معالجة!$B$3:$X$3,K$2,معالجة!$B$4:$X$4),"")) | ... V10: =IF(OR(V$2="",COUNT(الرصد!$C10:$Y10)=0),"",IFERROR(SUMIF(معالجة!$B$3:$X$3,V$2,الرصد!$C10:$Y10)/SUMIF(معالجة!$B$3:$X$3,V$2,معالجة!$B$4:$X$4),"")) | W10: =IFERROR(C10/المهارات!$G$27,"")
A11: حمد عيد عبدالكريم عيد الجاسم | B11: 10/1 | C11: =IF(COUNT(الرصد!C11:Y11)=0,"",SUM(الرصد!C11:Y11)) | D11: =IF(OR(D$2="",COUNT(الرصد!$C11:$Y11)=0),"",IFERROR(SUMIF(معالجة!$B$3:$X$3,D$2,الرصد!$C11:$Y11)/SUMIF(معالجة!$B$3:$X$3,D$2,معالجة!$B$4:$X$4),"")) | E11: =IF(OR(E$2="",COUNT(الرصد!$C11:$Y11)=0),"",IFERROR(SUMIF(معالجة!$B$3:$X$3,E$2,الرصد!$C11:$Y11)/SUMIF(معالجة!$B$3:$X$3,E$2,معالجة!$B$4:$X$4),"")) | F11: =IF(OR(F$2="",COUNT(الرصد!$C11:$Y11)=0),"",IFERROR(SUMIF(معالجة!$B$3:$X$3,F$2,الرصد!$C11:$Y11)/SUMIF(معالجة!$B$3:$X$3,F$2,معالجة!$B$4:$X$4),"")) | G11: =IF(OR(G$2="",COUNT(الرصد!$C11:$Y11)=0),"",IFERROR(SUMIF(معالجة!$B$3:$X$3,G$2,الرصد!$C11:$Y11)/SUMIF(معالجة!$B$3:$X$3,G$2,معالجة!$B$4:$X$4),"")) | H11: =IF(OR(H$2="",COUNT(الرصد!$C11:$Y11)=0),"",IFERROR(SUMIF(معالجة!$B$3:$X$3,H$2,الرصد!$C11:$Y11)/SUMIF(معالجة!$B$3:$X$3,H$2,معالجة!$B$4:$X$4),"")) | I11: =IF(OR(I$2="",COUNT(الرصد!$C11:$Y11)=0),"",IFERROR(SUMIF(معالجة!$B$3:$X$3,I$2,الرصد!$C11:$Y11)/SUMIF(معالجة!$B$3:$X$3,I$2,معالجة!$B$4:$X$4),"")) | J11: =IF(OR(J$2="",COUNT(الرصد!$C11:$Y11)=0),"",IFERROR(SUMIF(معالجة!$B$3:$X$3,J$2,الرصد!$C11:$Y11)/SUMIF(معالجة!$B$3:$X$3,J$2,معالجة!$B$4:$X$4),"")) | K11: =IF(OR(K$2="",COUNT(الرصد!$C11:$Y11)=0),"",IFERROR(SUMIF(معالجة!$B$3:$X$3,K$2,الرصد!$C11:$Y11)/SUMIF(معالجة!$B$3:$X$3,K$2,معالجة!$B$4:$X$4),"")) | ... V11: =IF(OR(V$2="",COUNT(الرصد!$C11:$Y11)=0),"",IFERROR(SUMIF(معالجة!$B$3:$X$3,V$2,الرصد!$C11:$Y11)/SUMIF(معالجة!$B$3:$X$3,V$2,معالجة!$B$4:$X$4),"")) | W11: =IFERROR(C11/المهارات!$G$27,"")
A12: سعود عثمان مرزوق فرج العبدالله | B12: 10/1 | C12: =IF(COUNT(الرصد!C12:Y12)=0,"",SUM(الرصد!C12:Y12)) | D12: =IF(OR(D$2="",COUNT(الرصد!$C12:$Y12)=0),"",IFERROR(SUMIF(معالجة!$B$3:$X$3,D$2,الرصد!$C12:$Y12)/SUMIF(معالجة!$B$3:$X$3,D$2,معالجة!$B$4:$X$4),"")) | E12: =IF(OR(E$2="",COUNT(الرصد!$C12:$Y12)=0),"",IFERROR(SUMIF(معالجة!$B$3:$X$3,E$2,الرصد!$C12:$Y12)/SUMIF(معالجة!$B$3:$X$3,E$2,معالجة!$B$4:$X$4),"")) | F12: =IF(OR(F$2="",COUNT(الرصد!$C12:$Y12)=0),"",IFERROR(SUMIF(معالجة!$B$3:$X$3,F$2,الرصد!$C12:$Y12)/SUMIF(معالجة!$B$3:$X$3,F$2,معالجة!$B$4:$X$4),"")) | G12: =IF(OR(G$2="",COUNT(الرصد!$C12:$Y12)=0),"",IFERROR(SUMIF(معالجة!$B$3:$X$3,G$2,الرصد!$C12:$Y12)/SUMIF(معالجة!$B$3:$X$3,G$2,معالجة!$B$4:$X$4),"")) | H12: =IF(OR(H$2="",COUNT(الرصد!$C12:$Y12)=0),"",IFERROR(SUMIF(معالجة!$B$3:$X$3,H$2,الرصد!$C12:$Y12)/SUMIF(معالجة!$B$3:$X$3,H$2,معالجة!$B$4:$X$4),"")) | I12: =IF(OR(I$2="",COUNT(الرصد!$C12:$Y12)=0),"",IFERROR(SUMIF(معالجة!$B$3:$X$3,I$2,الرصد!$C12:$Y12)/SUMIF(معالجة!$B$3:$X$3,I$2,معالجة!$B$4:$X$4),"")) | J12: =IF(OR(J$2="",COUNT(الرصد!$C12:$Y12)=0),"",IFERROR(SUMIF(معالجة!$B$3:$X$3,J$2,الرصد!$C12:$Y12)/SUMIF(معالجة!$B$3:$X$3,J$2,معالجة!$B$4:$X$4),"")) | K12: =IF(OR(K$2="",COUNT(الرصد!$C12:$Y12)=0),"",IFERROR(SUMIF(معالجة!$B$3:$X$3,K$2,الرصد!$C12:$Y12)/SUMIF(معالجة!$B$3:$X$3,K$2,معالجة!$B$4:$X$4),"")) | ... V12: =IF(OR(V$2="",COUNT(الرصد!$C12:$Y12)=0),"",IFERROR(SUMIF(معالجة!$B$3:$X$3,V$2,الرصد!$C12:$Y12)/SUMIF(معالجة!$B$3:$X$3,V$2,معالجة!$B$4:$X$4),"")) | W12: =IFERROR(C12/المهارات!$G$27,"")
A13: سيف بطى سيف البطى الكعبى | B13: 10/1 | C13: =IF(COUNT(الرصد!C13:Y13)=0,"",SUM(الرصد!C13:Y13)) | D13: =IF(OR(D$2="",COUNT(الرصد!$C13:$Y13)=0),"",IFERROR(SUMIF(معالجة!$B$3:$X$3,D$2,الرصد!$C13:$Y13)/SUMIF(معالجة!$B$3:$X$3,D$2,معالجة!$B$4:$X$4),"")) | E13: =IF(OR(E$2="",COUNT(الرصد!$C13:$Y13)=0),"",IFERROR(SUMIF(معالجة!$B$3:$X$3,E$2,الرصد!$C13:$Y13)/SUMIF(معالجة!$B$3:$X$3,E$2,معالجة!$B$4:$X$4),"")) | F13: =IF(OR(F$2="",COUNT(الرصد!$C13:$Y13)=0),"",IFERROR(SUMIF(معالجة!$B$3:$X$3,F$2,الرصد!$C13:$Y13)/SUMIF(معالجة!$B$3:$X$3,F$2,معالجة!$B$4:$X$4),"")) | G13: =IF(OR(G$2="",COUNT(الرصد!$C13:$Y13)=0),"",IFERROR(SUMIF(معالجة!$B$3:$X$3,G$2,الرصد!$C13:$Y13)/SUMIF(معالجة!$B$3:$X$3,G$2,معالجة!$B$4:$X$4),"")) | H13: =IF(OR(H$2="",COUNT(الرصد!$C13:$Y13)=0),"",IFERROR(SUMIF(معالجة!$B$3:$X$3,H$2,الرصد!$C13:$Y13)/SUMIF(معالجة!$B$3:$X$3,H$2,معالجة!$B$4:$X$4),"")) | I13: =IF(OR(I$2="",COUNT(الرصد!$C13:$Y13)=0),"",IFERROR(SUMIF(معالجة!$B$3:$X$3,I$2,الرصد!$C13:$Y13)/SUMIF(معالجة!$B$3:$X$3,I$2,معالجة!$B$4:$X$4),"")) | J13: =IF(OR(J$2="",COUNT(الرصد!$C13:$Y13)=0),"",IFERROR(SUMIF(معالجة!$B$3:$X$3,J$2,الرصد!$C13:$Y13)/SUMIF(معالجة!$B$3:$X$3,J$2,معالجة!$B$4:$X$4),"")) | K13: =IF(OR(K$2="",COUNT(الرصد!$C13:$Y13)=0),"",IFERROR(SUMIF(معالجة!$B$3:$X$3,K$2,الرصد!$C13:$Y13)/SUMIF(معالجة!$B$3:$X$3,K$2,معالجة!$B$4:$X$4),"")) | ... V13: =IF(OR(V$2="",COUNT(الرصد!$C13:$Y13)=0),"",IFERROR(SUMIF(معالجة!$B$3:$X$3,V$2,الرصد!$C13:$Y13)/SUMIF(معالجة!$B$3:$X$3,V$2,معالجة!$B$4:$X$4),"")) | W13: =IFERROR(C13/المهارات!$G$27,"")
A14: عبدالرحمن مبارك حسن بدو العبدالله | B14: 10/1 | C14: =IF(COUNT(الرصد!C14:Y14)=0,"",SUM(الرصد!C14:Y14)) | D14: =IF(OR(D$2="",COUNT(الرصد!$C14:$Y14)=0),"",IFERROR(SUMIF(معالجة!$B$3:$X$3,D$2,الرصد!$C14:$Y14)/SUMIF(معالجة!$B$3:$X$3,D$2,معالجة!$B$4:$X$4),"")) | E14: =IF(OR(E$2="",COUNT(الرصد!$C14:$Y14)=0),"",IFERROR(SUMIF(معالجة!$B$3:$X$3,E$2,الرصد!$C14:$Y14)/SUMIF(معالجة!$B$3:$X$3,E$2,معالجة!$B$4:$X$4),"")) | F14: =IF(OR(F$2="",COUNT(الرصد!$C14:$Y14)=0),"",IFERROR(SUMIF(معالجة!$B$3:$X$3,F$2,الرصد!$C14:$Y14)/SUMIF(معالجة!$B$3:$X$3,F$2,معالجة!$B$4:$X$4),"")) | G14: =IF(OR(G$2="",COUNT(الرصد!$C14:$Y14)=0),"",IFERROR(SUMIF(معالجة!$B$3:$X$3,G$2,الرصد!$C14:$Y14)/SUMIF(معالجة!$B$3:$X$3,G$2,معالجة!$B$4:$X$4),"")) | H14: =IF(OR(H$2="",COUNT(الرصد!$C14:$Y14)=0),"",IFERROR(SUMIF(معالجة!$B$3:$X$3,H$2,الرصد!$C14:$Y14)/SUMIF(معالجة!$B$3:$X$3,H$2,معالجة!$B$4:$X$4),"")) | I14: =IF(OR(I$2="",COUNT(الرصد!$C14:$Y14)=0),"",IFERROR(SUMIF(معالجة!$B$3:$X$3,I$2,الرصد!$C14:$Y14)/SUMIF(معالجة!$B$3:$X$3,I$2,معالجة!$B$4:$X$4),"")) | J14: =IF(OR(J$2="",COUNT(الرصد!$C14:$Y14)=0),"",IFERROR(SUMIF(معالجة!$B$3:$X$3,J$2,الرصد!$C14:$Y14)/SUMIF(معالجة!$B$3:$X$3,J$2,معالجة!$B$4:$X$4),"")) | K14: =IF(OR(K$2="",COUNT(الرصد!$C14:$Y14)=0),"",IFERROR(SUMIF(معالجة!$B$3:$X$3,K$2,الرصد!$C14:$Y14)/SUMIF(معالجة!$B$3:$X$3,K$2,معالجة!$B$4:$X$4),"")) | ... V14: =IF(OR(V$2="",COUNT(الرصد!$C14:$Y14)=0),"",IFERROR(SUMIF(معالجة!$B$3:$X$3,V$2,الرصد!$C14:$Y14)/SUMIF(معالجة!$B$3:$X$3,V$2,معالجة!$B$4:$X$4),"")) | W14: =IFERROR(C14/المهارات!$G$27,"")
... A222: يوسف امين مروان امين نزال | B222: 10/ESE | C222: =IF(COUNT(الرصد!C222:Y222)=0,"",SUM(الرصد!C222:Y222)) | D222: =IF(OR(D$2="",COUNT(الرصد!$C222:$Y222)=0),"",IFERROR(SUMIF(معالجة!$B$3:$X$3,D$2,الرصد!$C222:$Y222)/SUMIF(معالجة!$B$3:$X$3,D$2,معالجة!$B$4:$X$4),"")) | E222: =IF(OR(E$2="",COUNT(الرصد!$C222:$Y222)=0),"",IFERROR(SUMIF(معالجة!$B$3:$X$3,E$2,الرصد!$C222:$Y222)/SUMIF(معالجة!$B$3:$X$3,E$2,معالجة!$B$4:$X$4),"")) | F222: =IF(OR(F$2="",COUNT(الرصد!$C222:$Y222)=0),"",IFERROR(SUMIF(معالجة!$B$3:$X$3,F$2,الرصد!$C222:$Y222)/SUMIF(معالجة!$B$3:$X$3,F$2,معالجة!$B$4:$X$4),"")) | G222: =IF(OR(G$2="",COUNT(الرصد!$C222:$Y222)=0),"",IFERROR(SUMIF(معالجة!$B$3:$X$3,G$2,الرصد!$C222:$Y222)/SUMIF(معالجة!$B$3:$X$3,G$2,معالجة!$B$4:$X$4),"")) | H222: =IF(OR(H$2="",COUNT(الرصد!$C222:$Y222)=0),"",IFERROR(SUMIF(معالجة!$B$3:$X$3,H$2,الرصد!$C222:$Y222)/SUMIF(معالجة!$B$3:$X$3,H$2,معالجة!$B$4:$X$4),"")) | I222: =IF(OR(I$2="",COUNT(الرصد!$C222:$Y222)=0),"",IFERROR(SUMIF(معالجة!$B$3:$X$3,I$2,الرصد!$C222:$Y222)/SUMIF(معالجة!$B$3:$X$3,I$2,معالجة!$B$4:$X$4),"")) | J222: =IF(OR(J$2="",COUNT(الرصد!$C222:$Y222)=0),"",IFERROR(SUMIF(معالجة!$B$3:$X$3,J$2,الرصد!$C222:$Y222)/SUMIF(معالجة!$B$3:$X$3,J$2,معالجة!$B$4:$X$4),"")) | K222: =IF(OR(K$2="",COUNT(الرصد!$C222:$Y222)=0),"",IFERROR(SUMIF(معالجة!$B$3:$X$3,K$2,الرصد!$C222:$Y222)/SUMIF(معالجة!$B$3:$X$3,K$2,معالجة!$B$4:$X$4),"")) | ... V222: =IF(OR(V$2="",COUNT(الرصد!$C222:$Y222)=0),"",IFERROR(SUMIF(معالجة!$B$3:$X$3,V$2,الرصد!$C222:$Y222)/SUMIF(معالجة!$B$3:$X$3,V$2,معالجة!$B$4:$X$4),"")) | W222: =IFERROR(C222/المهارات!$G$27,"")
C223: =SUM(الرصد!C223:Y223) -> 0

Sheet معالجة
A1: ورقة مساعدة تلقائية – لا تُعدّل
A2: رقم السؤال | B2: =المهارات!E2 -> 1 | C2: =المهارات!E3 -> 2 | D2: =المهارات!E4 -> 3 | E2: =المهارات!E5 -> 4 | F2: =المهارات!E6 -> 5 | G2: =المهارات!E7 -> 6 | H2: =المهارات!E8 -> 7 | I2: =المهارات!E9 -> 8 | J2: =المهارات!E10 -> 9 | K2: =المهارات!E11 -> 10 | L2: =المهارات!E12 -> 11 | M2: =المهارات!E13 -> 12 | N2: =المهارات!E14 -> 13 | O2: =المهارات!E15 -> 14 | P2: =المهارات!E16 -> 15 | Q2: =المهارات!E17 -> 16 | R2: =المهارات!E18 -> 17 | S2: =المهارات!E19 -> 18 | T2: =المهارات!E20 -> 19 | U2: =المهارات!E21 -> 20 | V2: =المهارات!E22 -> 21 | W2: =المهارات!E23 -> 22 | X2: =المهارات!E24 -> 23
A3: المهارة | B3: =IF(المهارات!F2="","",المهارات!F2) | C3: =IF(المهارات!F3="","",المهارات!F3) | D3: =IF(المهارات!F4="","",المهارات!F4) | E3: =IF(المهارات!F5="","",المهارات!F5) | F3: =IF(المهارات!F6="","",المهارات!F6) | G3: =IF(المهارات!F7="","",المهارات!F7) | H3: =IF(المهارات!F8="","",المهارات!F8) | I3: =IF(المهارات!F9="","",المهارات!F9) | J3: =IF(المهارات!F10="","",المهارات!F10) | K3: =IF(المهارات!F11="","",المهارات!F11) | L3: =IF(المهارات!F12="","",المهارات!F12) | M3: =IF(المهارات!F13="","",المهارات!F13) | N3: =IF(المهارات!F14="","",المهارات!F14) | O3: =IF(المهارات!F15="","",المهارات!F15) | P3: =IF(المهارات!F16="","",المهارات!F16) | Q3: =IF(المهارات!F17="","",المهارات!F17) | R3: =IF(المهارات!F18="","",المهارات!F18) | S3: =IF(المهارات!F19="","",المهارات!F19) | T3: =IF(المهارات!F20="","",المهارات!F20) | U3: =IF(المهارات!F21="","",المهارات!F21) | V3: =IF(المهارات!F22="","",المهارات!F22) | W3: =IF(المهارات!F23="","",المهارات!F23) | X3: =IF(المهارات!F24="","",المهارات!F24)
A4: الدرجة الكلية | B4: =IF(المهارات!G2="",0,المهارات!G2) -> 0 | C4: =IF(المهارات!G3="",0,المهارات!G3) -> 0 | D4: =IF(المهارات!G4="",0,المهارات!G4) -> 0 | E4: =IF(المهارات!G5="",0,المهارات!G5) -> 0 | F4: =IF(المهارات!G6="",0,المهارات!G6) -> 0 | G4: =IF(المهارات!G7="",0,المهارات!G7) -> 0 | H4: =IF(المهارات!G8="",0,المهارات!G8) -> 0 | I4: =IF(المهارات!G9="",0,المهارات!G9) -> 0 | J4: =IF(المهارات!G10="",0,المهارات!G10) -> 0 | K4: =IF(المهارات!G11="",0,المهارات!G11) -> 0 | L4: =IF(المهارات!G12="",0,المهارات!G12) -> 0 | M4: =IF(المهارات!G13="",0,المهارات!G13) -> 0 | N4: =IF(المهارات!G14="",0,المهارات!G14) -> 0 | O4: =IF(المهارات!G15="",0,المهارات!G15) -> 0 | P4: =IF(المهارات!G16="",0,المهارات!G16) -> 0 | Q4: =IF(المهارات!G17="",0,المهارات!G17) -> 0 | R4: =IF(المهارات!G18="",0,المهارات!G18) -> 0 | S4: =IF(المهارات!G19="",0,المهارات!G19) -> 0 | T4: =IF(المهارات!G20="",0,المهارات!G20) -> 0 | U4: =IF(المهارات!G21="",0,المهارات!G21) -> 0 | V4: =IF(المهارات!G22="",0,المهارات!G22) -> 0 | W4: =IF(المهارات!G23="",0,المهارات!G23) -> 0 | X4: =IF(المهارات!G24="",0,المهارات!G24) -> 0
